
Restored from /home/seuyon0101/aiffel/MODEL/tf_cmsp16000_ckpt_final_0329_최종/ckpt-18
Bucket  3: 100%|█████████████████████| 2/2 [00:00<00:00,  3.23it/s, Loss 4.1130]
100%|████████████████████████████| 5/5 [00:00<00:00, 15.83it/s, val_Loss 3.1690]
Saved checkpoint for step 1: /home/seuyon0101/aiffel/MODEL/tf_cmsp16000_ckpt_final_0329_최종/ckpt-19






























































































































Bucket  2: 100%|███████████████| 1455/1455 [04:16<00:00,  5.68it/s, Loss 2.8752]
100%|████████████████████████████| 5/5 [00:00<00:00, 36.23it/s, val_Loss 3.0273]
Saved checkpoint for step 1: /home/seuyon0101/aiffel/MODEL/tf_cmsp16000_ckpt_final_0329_최종/ckpt-20

























































































































































































































































































































































































































































































































Bucket  1: 100%|█████████████| 13360/13360 [16:53<00:00, 13.18it/s, Loss 2.4311]
100%|████████████████████████████| 5/5 [00:00<00:00, 73.90it/s, val_Loss 3.3426]
Saved checkpoint for step 1: /home/seuyon0101/aiffel/MODEL/tf_cmsp16000_ckpt_final_0329_최종/ckpt-21













































































































100%|█████████████████████████████████████████| 125/125 [04:30<00:00,  2.16s/it]
--- Logging error ---
Traceback (most recent call last):
  File "/home/seuyon0101/anaconda3/envs/saturi/lib/python3.9/logging/__init__.py", line 1087, in emit
    self.flush()
  File "/home/seuyon0101/anaconda3/envs/saturi/lib/python3.9/logging/__init__.py", line 1067, in flush
    self.stream.flush()
OSError: [Errno 28] No space left on device
Call stack: